Workbook

Sheet READ ME
A1: Date | B1: 46082
A3: Description | B3: This file provides traceability from Business use case > workflow > task > user story & persona > description > acceptance criteria. It also contains functional requirements to enable the user stories
B4: the Plan_business_use_cases tab contains an export of the ADL JIRA advanced plan - relfecting the DLE Use Case taxonomy.
B5: the plan export does not contain details contained on the actual tickets
B6: the ERM project with Parent tab is an export of the ADL JIRA EDLM Requirements Management Project and contains key ticket details.
B7: The UseCase to Accept Criteria tab maps to 2 files together using Plan_business_use_cases: "Work item key" and ERM project with Parent "issue key"
B9: Many of these requirements can be visualized in the DLE Workflow UIUX PDFs.

Sheet Plan_business_use_cases
A1: Hierarchy | B1: Title | C1: Space | D1: Releases (roll-up) | E1: Releases | F1: Team (roll-up) | G1: Team | H1: Assignee | I1: Reporter | J1: Sprint (roll-up) | K1: Sprint | L1: Target start date | M1: Target end date | N1: Due date (roll-up) | O1: Due date | P1: Estimates (d) (roll-up) | Q1: Estimates (d) | R1: Parent | S1: Priority | T1: Labels | U1: Components | V1: Work item key | W1: Work item status | X1: Goal | Y1: Goal status | Z1: Idea | AA1: Progress (%) | AB1: Progress completed (d) | AC1: Progress remaining (d) | AD1: Progress (%) work item count (IC) | AE1: To do IC | AF1: In progress IC | AG1: Done IC | AH1: Total IC | AI1: Start date (roll-up) | AJ1: Start date | AK1: User Persona(s)
A2: Use Case | B2: Configure: DLE System Management | C2: DLE - Top Level Planning | F2: ADL Human Centered Design [EXT] | G2: ADL Human Centered Design [EXT] | I2: Hunter Smith | J2: EDLM Sprint 47, EDLM Sprint 48 | N2: 45910 | S2: Medium | V2: DTLP-43 | W2: Backlog | AA2: 0 | AB2: 0 | AC2: 0 | AD2: 0 | AE2: 3 | AF2: 0 | AG2: 0 | AH2: 3 | AI2: 45882
A3: Initiative | B3: Install & Configure DLE Systems | C3: DLE - Top Level Planning | F3: ADL Human Centered Design [EXT] | G3: ADL Human Centered Design [EXT] | I3: Hunter Smith | J3: EDLM Sprint 47, EDLM Sprint 48 | N3: 45910 | R3: Configure: DLE System Management | S3: Medium | U3: EDLM Moodle LMS | V3: DTLP-44 | W3: Backlog | AA3: 0 | AB3: 0 | AC3: 0 | AD3: 0 | AE3: 6 | AF3: 0 | AG3: 0 | AH3: 6 | AI3: 45882
A4: Epic | B4: Provision Organizational Tenancies (Domains) | C4: EDLM - Requirements Management | G4: ADL Human Centered Design [EXT] | I4: Hunter Smith | R4: Install & Configure DLE Systems | S4: Medium | V4: ERM-2093 | W4: Backlog | AA4: 0 | AB4: 0 | AC4: 0 | AD4: 0 | AE4: 0 | AF4: 0 | AG4: 0 | AH4: 0
A5: Epic | B5: Install TLA Reference Implementation Components | C5: EDLM - Requirements Management | G5: ADL Human Centered Design [EXT] | I5: Hunter Smith | R5: Install & Configure DLE Systems | S5: Medium | V5: ERM-2094 | W5: Backlog | AA5: 0 | AB5: 0 | AC5: 0 | AD5: 0 | AE5: 0 | AF5: 0 | AG5: 0 | AH5: 0
A6: Epic | B6: Configure Software, Databases, and Services | C6: EDLM - Requirements Management | F6: ADL Human Centered Design [EXT] | G6: ADL Human Centered Design [EXT] | I6: Hunter Smith | R6: Install & Configure DLE Systems | S6: Medium | U6: EDLM Moodle LMS, EDLM Portal | V6: ERM-2095 | W6: Backlog | AA6: 0 | AB6: 0 | AC6: 0 | AD6: 33.33 | AE6: 4 | AF6: 0 | AG6: 2 | AH6: 6
A7: Story | B7: As an [Administrator], I want to import multiple P2881 profiles into the ECC data model | C7: EDLM - Requirements Management | G7: ADL Human Centered Design [EXT] | I7: Hunter Smith | R7: Configure Software, Databases, and Services | S7: Medium | U7: ecc/ecc-openlxp-xis | V7: ERM-2228 | W7: Backlog | AA7: 0 | AB7: 0 | AC7: 0 | AD7: 0 | AE7: 0 | AF7: 0 | AG7: 0 | AH7: 0 | AK7: EDLM Schema Administrator
A8: Story | B8: As an [Experience Manager], I want to preview and sync course catalog page layouts with the structure of ingested content profiles | C8: EDLM - Requirements Management | G8: ADL Human Centered Design [EXT] | I8: Hunter Smith | R8: Configure Software, Databases, and Services | S8: Medium | U8: ldss/openlxp-xms | V8: ERM-2229 | W8: Backlog | AA8: 0 | AB8: 0 | AC8: 0 | AD8: 0 | AE8: 0 | AF8: 0 | AG8: 0 | AH8: 0 | AK8: EDLM Experience Manager
A9: Story | B9: As a [System Admin], I want access to help desk to customize the configuration of my DLE environment | C9: EDLM - Requirements Management | G9: ADL Human Centered Design [EXT] | I9: Ashley Howell | R9: Configure Software, Databases, and Services | S9: Medium | V9: ERM-147 | W9: Backlog | AA9: 0 | AB9: 0 | AC9: 0 | AD9: 0 | AE9: 0 | AF9: 0 | AG9: 0 | AH9: 0 | AK9: EDLM IT System Administrator
A10: Story | B10: As a [System Admin], I want to set up different course catalog spotlights for different DHRA customers within the EDLM Portal | C10: EDLM - Requirements Management | G10: ADL Human Centered Design [EXT] | R10: Configure Software, Databases, and Services | S10: Medium | U10: EDLM Portal | V10: ERM-2701 | W10: Backlog | AA10: 0 | AB10: 0 | AC10: 0 | AD10: 0 | AE10: 0 | AF10: 0 | AG10: 0 | AH10: 0
A11: Epic | B11: Set up identity and access management | C11: EDLM - Requirements Management | F11: ADL Human Centered Design [EXT] | G11: ADL Human Centered Design [EXT] | I11: Hunter Smith | J11: EDLM Sprint 47, EDLM Sprint 48 | N11: 45910 | R11: Install & Configure DLE Systems | S11: Medium | V11: ERM-2713 | W11: Backlog | AA11: 0 | AB11: 0 | AC11: 0 | AD11: 0 | AE11: 3 | AF11: 0 | AG11: 0 | AH11: 3 | AI11: 45882
A12: Story | B12: As a [Site Admin] I would like to be able to configure the ECCR utilize JWT for user auth | C12: EDLM - Requirements Management | G12: ADL Human Centered Design [EXT] | I12: Hunter Smith | K12: EDLM Sprint 48 [EXT] [COMPLETED] + EDLM Sprint 47 [EXT] [COMPLETED] | R12: Set up identity and access management | S12: Medium | U12: eccr/frontend, eccr/backend | V12: ERM-294 | W12: Backlog | AA12: 0 | AB12: 0 | AC12: 0 | AD12: 0 | AE12: 0 | AF12: 0 | AG12: 0 | AH12: 0 | AK12: EDLM IT System Administrator
A13: Story | B13: As a [Competency Manager], I want my credentials (e.g., name) to be populated when I log in so that I can easily confirm that I am accessing my account. | C13: EDLM - Requirements Management | G13: ADL Human Centered Design [EXT] | I13: Ashley Howell | R13: Set up identity and access management | S13: Medium | V13: ERM-350 | W13: Backlog | AA13: 0 | AB13: 0 | AC13: 0 | AD13: 0 | AE13: 0 | AF13: 0 | AG13: 0 | AH13: 0 | AK13: EDLM Competency Manager
A14: Story | B14: As a Competency Manager, I want my credentials (e.g., name) to be populated when I log in so that I can easily confirm that I am accessing my account. | C14: EDLM - Requirements Management | G14: ADL Human Centered Design [EXT] | R14: Set up identity and access management | S14: Medium | V14: ERM-1554 | W14: Backlog | AA14: 0 | AB14: 0 | AC14: 0 | AD14: 0 | AE14: 0 | AF14: 0 | AG14: 0 | AH14: 0
A15: Epic | B15: Integrate with existing DoD Infrastructure | C15: EDLM - Requirements Management | G15: ADL Human Centered Design [EXT] | I15: Hunter Smith | R15: Install & Configure DLE Systems | S15: Medium | U15: EDLM Portal | V15: ERM-2714 | W15: Backlog | AA15: 0 | AB15: 0 | AC15: 0 | AD15: 0 | AE15: 1 | AF15: 0 | AG15: 0 | AH15: 1 | AK15: EDLM IT System Admin
A16: Story | B16: As an [ADL Admin], I want to configure Zendesk so I can integrate the defined business rules and workflows | C16: EDLM - Requirements Management | H16: Desiree Esiere | R16: Integrate with existing DoD Infrastructure | S16: High | T16: Zendesk_DANTES | U16: EDLM Portal | V16: ERM-2832 | W16: Backlog | AA16: 0 | AB16: 0 | AC16: 0 | AD16: 0 | AE16: 0 | AF16: 0 | AG16: 0 | AH16: 0 | AK16: EDLM IT System Admin
A17: Epic | B17: Validate System Readiness | C17: EDLM - Requirements Management | G17: ADL Human Centered Design [EXT] | I17: Hunter Smith | R17: Install & Configure DLE Systems | S17: Medium | V17: ERM-2715 | W17: Backlog | AA17: 0 | AB17: 0 | AC17: 0 | AD17: 0 | AE17: 0 | AF17: 0 | AG17: 0 | AH17: 0
A18: Initiative | B18: Maintenance: Cybersecurity / Patches / Updates | C18: DLE - Top Level Planning | G18: ADL Human Centered Design [EXT] | I18: Hunter Smith | R18: Configure: DLE System Management | S18: Medium | V18: DTLP-45 | W18: Backlog | AA18: 0 | AB18: 0 | AC18: 0 | AD18: 0 | AE18: 0 | AF18: 0 | AG18: 0 | AH18: 0
A19: Initiative | B19: Help Desk & Support | C19: DLE - Top Level Planning | G19: ADL Human Centered Design [EXT] | I19: Hunter Smith | R19: Configure: DLE System Management | S19: Medium | V19: DTLP-46 | W19: Backlog | AA19: 0 | AB19: 0 | AC19: 0 | AD19: 0 | AE19: 0 | AF19: 0 | AG19: 0 | AH19: 0
A20: Use Case | B20: Configure: TLA Data Management | C20: DLE - Top Level Planning | F20: ADL RD&E [EXT], ADL Human Centered Design [EXT], Deloitte [EXT] | G20: ADL Human Centered Design [EXT] | I20: Hunter Smith | S20: Medium | V20: DTLP-38 | W20: Backlog | AA20: 0 | AB20: 0 | AC20: 0 | AD20: 0 | AE20: 4 | AF20: 0 | AG20: 0 | AH20: 4
A21: Initiative | B21: Manage a Language Set | C21: DLE - Top Level Planning | F21: ADL RD&E [EXT], ADL Human Centered Design [EXT], Deloitte [EXT] | G21: ADL Human Centered Design [EXT] | I21: Hunter Smith | R21: Configure: TLA Data Management | S21: Medium | U21: EDLM LDSS | V21: DTLP-39 | W21: Backlog | AA21: 0 | AB21: 0 | AC21: 0 | AD21: 0 | AE21: 4 | AF21: 0 | AG21: 0 | AH21: 4
A22: Epic | B22: [LDSS] Configure Language Set | C22: EDLM - Requirements Management | I22: Hunter Smith | R22: Manage a Language Set | S22: Medium | U22: EDLM LDSS | V22: ERM-2098 | W22: Backlog | AA22: 0 | AB22: 0 | AC22: 0 | AD22: 0 | AE22: 0 | AF22: 0 | AG22: 0 | AH22: 0
A23: Epic | B23: [LDSS] Create a Language Set | C23: EDLM - Requirements Management | F23: ADL RD&E [EXT], ADL Human Centered Design [EXT], Deloitte [EXT] | G23: ADL Human Centered Design [EXT] | H23: Andy Johnson | I23: Hunter Smith | R23: Manage a Language Set | S23: Medium | U23: EDLM LDSS, P2881 Learning Experience Metadata | V23: ERM-2099 | W23: Backlog | AA23: 0 | AB23: 0 | AC23: 0 | AD23: 9.09 | AE23: 20 | AF23: 0 | AG23: 2 | AH23: 22
A24: Story | B24: As a [Glossary Manager], when Indexing a LanguageSet, I would like to upload a LanguageSets file to index the terms and definitions it contains | C24: EDLM - Requirements Management | G24: ADL Human Centered Design [EXT] | I24: Hunter Smith | R24: [LDSS] Create a Language Set | S24: Medium | U24: EDLM LDSS, ldss/openlxp-xss, ldss-xss/CCV-LCV, ldss/openlxp-xss-ui | V24: ERM-462 | W24: Backlog | AA24: 0 | AB24: 0 | AC24: 0 | AD24: 0 | AE24: 0 | AF24: 0 | AG24: 0 | AH24: 0 | AK24: EDLM Glossary Manager
A25: Story | B25: As a [Glossary Manager] I would like to save my LanguageSet as a draft to resume later | C25: EDLM - Requirements Management | G25: ADL Human Centered Design [EXT] | I25: Hunter Smith | R25: [LDSS] Create a Language Set | S25: Medium | U25: EDLM LDSS, ldss/openlxp-xss, ldss-xss/CCV-LCV, ldss/openlxp-xss-ui | V25: ERM-514 | W25: Backlog | AA25: 0 | AB25: 0 | AC25: 0 | AD25: 0 | AE25: 0 | AF25: 0 | AG25: 0 | AH25: 0 | AK25: EDLM Glossary Manager
A26: Story | B26: As a [Glossary Manager] I would like to fully define term definitions | C26: EDLM - Requirements Management | G26: ADL Human Centered Design [EXT] | I26: Florian Tolk | R26: [LDSS] Create a Language Set | S26: Medium | U26: EDLM LDSS, ldss/openlxp-xss, ldss-xss/CCV-LCV, ldss/openlxp-xss-ui | V26: ERM-470 | W26: Backlog | AA26: 0 | AB26: 0 | AC26: 0 | AD26: 0 | AE26: 0 | AF26: 0 | AG26: 0 | AH26: 0 | AK26: EDLM Glossary Manager
A27: Story | B27: As a [Glossary Manager], when Registering Terms, I would like the ability to input a definition for a Term (CCVID) | C27: EDLM - Requirements Management | G27: ADL Human Centered Design [EXT] | I27: Hunter Smith | R27: [LDSS] Create a Language Set | S27: Medium | U27: EDLM LDSS, ldss/openlxp-xss, ldss-xss/CCV-LCV, ldss/openlxp-xss-ui | V27: ERM-497 | W27: Backlog | AA27: 0 | AB27: 0 | AC27: 0 | AD27: 0 | AE27: 0 | AF27: 0 | AG27: 0 | AH27: 0 | AK27: EDLM Glossary Manager
A28: Story | B28: As a [Glossary Manager], when Registering Terms, i would like to capture Context, Context Description, and Labels for a Term (CCVID) | C28: EDLM - Requirements Management | G28: ADL Human Centered Design [EXT] | I28: Hunter Smith | R28: [LDSS] Create a Language Set | S28: Medium | U28: EDLM LDSS, ldss/openlxp-xss, ldss-xss/CCV-LCV, ldss/openlxp-xss-ui | V28: ERM-1033 | W28: Backlog | AA28: 0 | AB28: 0 | AC28: 0 | AD28: 0 | AE28: 0 | AF28: 0 | AG28: 0 | AH28: 0 | AK28: EDLM Glossary Manager
A29: Story | B29: As a [Glossary Manager] when Registering Terms, I would like there to be a deconfliction service that notifies me if my desired definition already exists and point me to the correct term within that language set | C29: EDLM - Requirements Management | G29: ADL Human Centered Design [EXT] | I29: Hunter Smith | R29: [LDSS] Create a Language Set | S29: Medium | U29: EDLM LDSS, ldss/openlxp-xss, ldss-xss/CCV-LCV, ldss/openlxp-xss-ui | V29: ERM-498 | W29: Backlog | AA29: 0 | AB29: 0 | AC29: 0 | AD29: 0 | AE29: 0 | AF29: 0 | AG29: 0 | AH29: 0 | AK29: EDLM Glossary Manager
A30: Story | B30: As a [Glossary Manager] I would like to recieve a notification when a definition for a term with a similar context already exists within the uploaded languageSet | C30: EDLM - Requirements Management | G30: ADL Human Centered Design [EXT] | I30: Hunter Smith | R30: [LDSS] Create a Language Set | S30: Medium | U30: EDLM LDSS, ldss/openlxp-xss, ldss-xss/CCV-LCV, ldss/openlxp-xss-ui | V30: ERM-515 | W30: Backlog | AA30: 0 | AB30: 0 | AC30: 0 | AD30: 0 | AE30: 0 | AF30: 0 | AG30: 0 | AH30: 0 | AK30: EDLM Glossary Manager
A31: Story | B31: As a [Glossary Manager], I want to drag and drop a file to upload a language set | C31: EDLM - Requirements Management | G31: ADL Human Centered Design [EXT] | I31: Ashley Howell | R31: [LDSS] Create a Language Set | S31: Medium | U31: EDLM LDSS, ldss/openlxp-xss, ldss-xss/CCV-LCV, ldss/openlxp-xss-ui | V31: ERM-1000 | W31: Backlog | AA31: 0 | AB31: 0 | AC31: 0 | AD31: 0 | AE31: 0 | AF31: 0 | AG31: 0 | AH31: 0 | AK31: EDLM Glossary Manager
A32: Story | B32: As a [Glossary Manager], I want to preview the language file that I uploaded so I can ensure I am uploading the correct language set | C32: EDLM - Requirements Management | G32: ADL Human Centered Design [EXT] | I32: Ashley Howell | R32: [LDSS] Create a Language Set | S32: Medium | U32: EDLM LDSS, ldss/openlxp-xss, ldss-xss/CCV-LCV, ldss/openlxp-xss-ui | V32: ERM-1001 | W32: Backlog | AA32: 0 | AB32: 0 | AC32: 0 | AD32: 0 | AE32: 0 | AF32: 0 | AG32: 0 | AH32: 0 | AK32: EDLM Glossary Manager
A33: Story | B33: As a [Glossary Manager], I want to see the different terms and definitions that are aligned to terms within my language set | C33: EDLM - Requirements Management | G33: ADL Human Centered Design [EXT] | I33: Ashley Howell | R33: [LDSS] Create a Language Set | S33: Medium | U33: EDLM LDSS, ldss/openlxp-xss, ldss-xss/CCV-LCV, ldss/openlxp-xss-ui | V33: ERM-1002 | W33: Backlog | AA33: 0 | AB33: 0 | AC33: 0 | AD33: 0 | AE33: 0 | AF33: 0 | AG33: 0 | AH33: 0 | AK33: EDLM Glossary Manager
A34: Story | B34: As a [Glossary Manager], I want to see the alignment percentage for a term and definition that is aligned to terms within my language set | C34: EDLM - Requirements Management | G34: ADL Human Centered Design [EXT] | I34: Ashley Howell | R34: [LDSS] Create a Language Set | S34: Low | U34: EDLM LDSS, ldss/openlxp-xss, ldss-xss/CCV-LCV, ldss/openlxp-xss-ui | V34: ERM-1003 | W34: Backlog | AA34: 0 | AB34: 0 | AC34: 0 | AD34: 0 | AE34: 0 | AF34: 0 | AG34: 0 | AH34: 0 | AK34: EDLM Glossary Manager
A35: Story | B35: As a [Glossary Manager], I want to select a term's definition that I want to use and add a tag to it for my term within a language set | C35: EDLM - Requirements Management | G35: ADL Human Centered Design [EXT] | I35: Ashley Howell | R35: [LDSS] Create a Language Set | S35: Medium | U35: EDLM LDSS, ldss/openlxp-xss, ldss-xss/CCV-LCV, ldss/openlxp-xss-ui | V35: ERM-1004 | W35: Backlog | AA35: 0 | AB35: 0 | AC35: 0 | AD35: 0 | AE35: 0 | AF35: 0 | AG35: 0 | AH35: 0 | AK35: EDLM Glossary Manager
A36: Epic | B36: [LDSS] Edit a Language Set | C36: EDLM - Requirements Management | F36: ADL Human Centered Design [EXT] | G36: ADL Human Centered Design [EXT] | I36: Hunter Smith | R36: Manage a Language Set | S36: Medium | U36: EDLM LDSS | V36: ERM-2100 | W36: Backlog | AA36: 0 | AB36: 0 | AC36: 0 | AD36: 0 | AE36: 11 | AF36: 0 | AG36: 0 | AH36: 11
A37: Story | B37: As a [Glossary Manager], I want to see all of my language sets so I can view them in one place | C37: EDLM - Requirements Management | G37: ADL Human Centered Design [EXT] | I37: Ashley Howell | R37: [LDSS] Edit a Language Set | S37: High | U37: EDLM LDSS, ldss/openlxp-xss, ldss-xss/CCV-LCV | V37: ERM-997 | W37: Backlog | AA37: 0 | AB37: 0 | AC37: 0 | AD37: 0 | AE37: 0 | AF37: 0 | AG37: 0 | AH37: 0 | AK37: EDLM Glossary Manager
A38: Story | B38: As a [Glossary Manager], I want to expand/collapse a selected language set so I can see all associated terms and relationships | C38: EDLM - Requirements Management | G38: ADL Human Centered Design [EXT] | I38: Ashley Howell | R38: [LDSS] Edit a Language Set | S38: Medium | U38: EDLM LDSS, ldss/openlxp-xss, ldss-xss/CCV-LCV | V38: ERM-998 | W38: Backlog | AA38: 0 | AB38: 0 | AC38: 0 | AD38: 0 | AE38: 0 | AF38: 0 | AG38: 0 | AH38: 0 | AK38: EDLM Glossary Manager
A39: Story | B39: As a [Glossary Manager], I would like to search for terms based on keywords within the definitions | C39: EDLM - Requirements Management | G39: ADL Human Centered Design [EXT] | I39: Hunter Smith | R39: [LDSS] Edit a Language Set | S39: Medium | U39: EDLM LDSS, ldss/openlxp-xss, ldss-xss/CCV-LCV | V39: ERM-528 | W39: Backlog | AA39: 0 | AB39: 0 | AC39: 0 | AD39: 0 | AE39: 0 | AF39: 0 | AG39: 0 | AH39: 0 | AK39: EDLM Glossary Manager
A40: Story | B40: As a [Glossary Manager], I would like to search for terms based on the UID, Context, and Context Description | C40: EDLM - Requirements Management | G40: ADL Human Centered Design [EXT] | I40: Hunter Smith | R40: [LDSS] Edit a Language Set | S40: Medium | U40: ldss/openlxp-xss, ldss-xss/CCV-LCV | V40: ERM-536 | W40: Backlog | AA40: 0 | AB40: 0 | AC40: 0 | AD40: 0 | AE40: 0 | AF40: 0 | AG40: 0 | AH40: 0 | AK40: EDLM Glossary Manager
...

Sheet ERM project with Parent
A1: Issue Type | B1: Issue key | C1: Issue id | D1: Summary | E1: Description | F1: Custom field (Acceptance Criteria) | G1: Custom field (Acceptance Criteria) | H1: Parent | I1: Parent key | J1: Parent summary | K1: Status | L1: Components | M1: Components | N1: Components | O1: Components | P1: Components | Q1: Components | R1: Components | S1: Components | T1: Components | U1: Components | V1: Components | W1: Components | X1: Components | Y1: Components | Z1: Components | AA1: Components | AB1: Components | AC1: Components | AD1: Components | AE1: Components | AF1: Labels | AG1: Labels | AH1: Labels | AI1: Labels | AJ1: Labels
A2: Epic | B2: ERM-3384 | C2: 11527177 | D2: Audit data within the system | H2: 11522561 | I2: DTLP-81 | J2: Monitoring & Auditing | K2: Backlog
A3: Epic | B3: ERM-3383 | C3: 11527175 | D3: View Dashboards to monitor and relfect on progress and performance | H3: 11527173 | I3: DTLP-92 | J3: Monitor Staffing Plan | K3: Backlog
A4: Story | B4: ERM-3382 | C4: 11527171 | D4: As a Learner, I want to see which courses align with the my targeted role or specific competency gap | H4: 11517533 | I4: ERM-1096 | J4: [Portal] Identify Learning Activities or Courses for Learning Plan | K4: Backlog
A5: Story | B5: ERM-3381 | C5: 11527169 | D5: As a Learner, I want to see the percentage of competency alignment for courses that teach competencies aligned to my goal(s) | H5: 11517533 | I5: ERM-1096 | J5: [Portal] Identify Learning Activities or Courses for Learning Plan | K5: Backlog
A6: Story | B6: ERM-3379 | C6: 11526932 | D6: As a [Org (NOVA) Admin], I want to view and sort or organize individual applicant data | E6: As a NOVA Admin, I want to view and organize individual applicant data so I can easily manage all applications assigned to me during the current application cycle. In the SAPRO Portal, I can see a clear count of the total number of active applications I have, and I can use a global search bar to quickly locate an applicant by name. To help me narrow and reorganize the list, I can apply filters for *Application Type* (New or Renewal) and *Position*, and I can sort the table by key fields—including *Last Name*, *First Name*, *Type*, *Position*, and *Received Date*. This allows me to structure the data in the way that best supports my review workflow. From the table, I can view each individual application or download the applicant’s full packet directly from the portal. I also have access to full pagination controls, enabling me to navigate through large volumes of applications efficiently. | F6: Viewing Applications Given I am logged into the SAPRO Portal When I land on the Applications page Then I should see a table listing all applications assigned to me And I should see the total number of active applications displayed Searching for an Applicant Given I am on the Applications page When I enter a name into the search bar And I click the search icon or press enter Then the table should update to show only applications matching my search term Filtering Applications Scenario: Filter by Application Type Given application type filters are visible When I select “New” or “Renewal” Then the table should display only applications that match the selected type Scenario: Filter by Position Given position filters are visible When I select one or more positions Then the table should display only applications for those positions Scenario: Clear All Filters Given I have applied one or more filters When I click “Clear All Filters” Then all filters should be removed And the full list of applications should be displayed Sorting Applicant Data Scenario: Sort by Last Name Given the table contains applicant data When I click the “Last Name” column header Then the data should sort in ascending order And when I click it again Then it should sort in descending order Repeat logic for each sortable column: - First Name - Type - Position - Received Date Viewing and Downloading Applications Scenario: View Application Given I am on the Applications page When I click “View Application” for an applicant Then the system should open or display the application details Scenario: Download Application Given I am on the Applications page When I click “Download Application” Then the application file should begin downloading to my device Pagination Given there are more applications than can fit on one page When I use the pagination controls (page numbers or previous/next) Then I should be able to navigate between pages of applications Scenario: Jump to Page Given I see the “Jump to” pagination control When I enter a page number and click “Go” Then I should be taken directly to that page of results | H6: 11526586 | I6: ERM-3368 | J6: Package Application | K6: Backlog | L6: EDLM Portal | AF6: SAPRO
A7: Story | B7: ERM-3378 | C7: 11526728 | D7: As a [Academic Institution Registrar], I want to opt in/out of transcript status update notifications | E7: As an Academic Institute using the MMT Portal, I want a *Settings* page—reachable from the left navigation and from the profile menu in the top‑right—where I can see *all notification types available for my role* and *opt in or out of email notifications* at a big and at a small level, so I can control what updates I receive and where they are delivered. When I *opt into email notifications*, I can toggle individual event types: * *Delivered* and the page clearly displays the *email address* where my updates will be sent. If I *turn off* email notifications, the per‑event toggles become disabled to make it obvious I won’t receive any emails. Whenever my *transcript status is updated*, I receive an *email notification* that uses the approved template for the corresponding status. Templates: DELIVERED Dear User, Your Academic Institute has received a transcript from a DoD Service Member. Please log in to the MMT Portal ([+https://mmt.dso.mil/academicInstitute+|https://mmt.staging.dso.mil/academicInstitute]) to review the details and take any necessary actions. Thank you for using the MMT system. [MMT Portal Access Link] | F7: Background: An Academic Institute is logged into the MMT Portal. The user has access to a Settings page, accessible from both the left navigation and the profile menu in the top-right. The Settings page displays all notification types available for the user’s role and allows the user to opt in or out of email notifications at both a global and per-event level. The page also displays the email address where notifications will be sent. Scenario 1: Accessing the Settings Page Given the user is logged into the MMT Portal When the user clicks on "Settings" from the left navigation or the profile menu Then the user is taken to the Settings page And the page displays all notification types available for the user’s role And the page displays the email address where notifications will be sent Scenario 2: Opting In to Email Notifications Given the user is on the Settings page And email notifications are currently turned off When the user toggles the global email notifications switch to "On" Then the per-event notification toggles ("Delivered") become enabled And the user can select which event types to receive email notifications for Scenario 3: Opting Out of Email Notifications Given the user is on the Settings page And email notifications are currently turned on When the user toggles the global email notifications switch to "Off" Then all per-event notification toggles become disabled And it is visually clear that no email notifications will be sent Scenario 4: Per-Event Notification Toggle Given the user has email notifications turned on When the user toggles the "Delivered" event notification on or off Then the system updates the user’s preferences for that event type And only selected event types will trigger email notifications Scenario 5: Displaying Notification Email Address Given the user is on the Settings page When the page loads Then the email address where notifications will be sent is clearly displayed Scenario 6: Transcript Status Update - Delivered Given the user has opted in to receive "Delivered" email notifications When the user’s transcript status is updated to "Delivered" Then the user receives an email notification using the approved "DELIVERED" template And the email includes a link to the MMT Portal ( Appgate SDP) Scenario 7: No Email Sent When Opted Out Given the user has opted out of all email notifications When the user’s transcript status is updated to any status Then the user does not receive any email notification | H7: 11523053 | I7: ERM-2636 | J7: [MMT] Monitor Application | K7: To Do
A8: Story | B8: ERM-3377 | C8: 11526727 | D8: As a [Service Member/Veteran], I want to opt in/out of transcript status update notifications | E8: As a Service Member using the MMT Portal, I want a *Settings* page—reachable from the left navigation and from the profile menu in the top‑right—where I can see *all notification types available for my role* and *opt in or out of email notifications* at a big and at a small level, so I can control what updates I receive and where they are delivered. When I *opt into email notifications*, I can toggle individual event types: * *Delivered* * *Accessed* and the page clearly displays the *email address* where my updates will be sent. If I *turn off* email notifications, the per‑event toggles become disabled to make it obvious I won’t receive any emails. Whenever my *transcript status is updated*, I receive an *email notification* that uses the approved template for the corresponding status. Templates: DELIVERED Dear User, Your transcript has been successfully *delivered* to an academic institution. Please log in to the MMT Portal ([https://mmt.apps.dso.mil/|https://mmt.apps.dso.mil/|smart-link] ) to review the details and take any necessary actions. Thank you for using the MMT system. [MMT Portal Access Link] ACCESSED Dear User, Your transcript has been successfully *accessed* by an academic institution. Please log in to the MMT Portal ([https://mmt.apps.dso.mil/|https://mmt.apps.dso.mil/|smart-link] ) to review the details and take any necessary actions. Thank you for using the MMT system. [MMT Portal Access Link] | F8: Background: A Service Member or Veteran is logged into the MMT Portal. The user has access to a Settings page, accessible from both the left navigation and the profile menu in the top-right. The Settings page displays all notification types available for the user’s role and allows the user to opt in or out of email notifications at both a global and per-event level. The page also displays the email address where notifications will be sent. Scenario 1: Accessing the Settings Page Given the user is logged into the MMT Portal When the user clicks on "Settings" from the left navigation or the profile menu Then the user is taken to the Settings page And the page displays all notification types available for the user’s role And the page displays the email address where notifications will be sent Scenario 2: Opting In to Email Notifications Given the user is on the Settings page And email notifications are currently turned off When the user toggles the global email notifications switch to "On" Then the per-event notification toggles ("Delivered", "Accessed") become enabled And the user can select which event types to receive email notifications for Scenario 3: Opting Out of Email Notifications Given the user is on the Settings page And email notifications are currently turned on When the user toggles the global email notifications switch to "Off" Then all per-event notification toggles become disabled And it is visually clear that no email notifications will be sent Scenario 4: Per-Event Notification Toggle Given the user has email notifications turned on When the user toggles the "Delivered" or "Accessed" event notification on or off Then the system updates the user’s preferences for that event type And only selected event types will trigger email notifications Scenario 5: Displaying Notification Email Address Given the user is on the Settings page When the page loads Then the email address where notifications will be sent is clearly displayed Scenario 6: Transcript Status Update - Delivered Given the user has opted in to receive "Delivered" email notifications When the user’s transcript status is updated to "Delivered" Then the user receives an email notification using the approved "DELIVERED" template And the email includes a link to the MMT Portal ( Appgate SDP) Scenario 7: Transcript Status Update - Accessed Given the user has opted in to receive "Accessed" email notifications When the user’s transcript status is updated to "Accessed" Then the user receives an email notification using the approved "ACCESSED" template And the email includes a link to the MMT Portal ( Appgate SDP) Scenario 8: No Email Sent When Opted Out Given the user has opted out of all email notifications When the user’s transcript status is updated to any status Then the user does not receive any email notification | H8: 11523053 | I8: ERM-2636 | J8: [MMT] Monitor Application | K8: To Do
A9: Story | B9: ERM-3373 | C9: 11526658 | D9: As a [Learner], I want to upload certifications for CEU courses I have taken | E9: This requirement would only appear for Renewal applications. For each course I add to my ‘Completed Continuing Education Hours’ section, I want to upload a file of my certification that shows I completed that course. | H9: 11523894 | I9: ERM-2865 | J9: Initiate Application | K9: Backlog
A10: Story | B10: ERM-3371 | C10: 11526623 | D10: As a [Learner], I want to read and acknowledge the code of ethics so it is clear that I understand them | E10: * As a [Learner], I want to read and acknowledge the code of ethics during the application process so that it is clear I understand and agree to the ethical standards required. * The application must present the full text of the code of ethics to the learner. * The learner must be required to check a box or provide an electronic signature to acknowledge they have read and understood the code of ethics before proceeding. * This step is mandatory and must be completed before the application can be submitted. * The system should track this acknowledgment (e.g., via an xAPI statement) for auditing and compliance purposes. * This requirement is part of the MVP and should be included under the "initiate application" workflow. Here is the updated Code of Ethics Language: Every DoD Sexual Assault Response Workforce (SARW) Professional must act with integrity, treat all victims of sexual assault crimes with dignity and compassion, and uphold principles of justice for accused and accuser alike. To these ends, this Code will govern the conduct of DoD SARW Professionals: I. In relationships with every victim, the DoD SARW professionals shall: # Recognize the interests of the victim as a primary responsibility. # Respect the victim's civil and legal rights, subject only to laws requiring disclosure of information to appropriate other sources. # Respect the victim's rights to privacy and confidentiality, subject only to laws requiring disclosure. # Respond compassionately to each victim with personalized services. # Accept the victim's statement of events as it is told, withholding opinion or judgment, whether or not a suspected offender has been identified, arrested, convicted, or acquitted. # Provide services to every victim, within policy guidelines set by the DoD and the Services, without attributing blame, no matter what the victim's conduct was at the time of the victimization or at another stage of the victim’s life. # Foster maximum self-determination on the part of the victim. # Serve as a victim advocate when assigned, and in that capacity, act on behalf of the victim's stated needs and within policy guidelines set by DoD and the Services. # Should one victim's needs conflict with another's, act with regard to one victim only after promptly referring the other to another qualified DoD SARW professional. # Have no personal or sexual relations with victims currently supported by DoD SARW professionals or with alleged offenders, in recognition that to do so risks exploitation of the knowledge and trust derived from the professional relationship. # Make victim referrals to other resources or services only in the victim's best interest, avoiding any conflict of interest in the process, and do so in accordance with DoD regulations. II. In relationships with colleagues, other professionals, and the public, the DoD SARW professionals shall: # Conduct relationships with colleagues in such a way as to promote mutual respect and improvement of service. # Conduct relationships with allied professionals such that they are given equal respect and dignity as professionals in the victim assistance field. # Take steps to quell negative, insubstantial rumors about colleagues and allied professionals. # Share knowledge and encourage proficiency and excellence in victim assistance among colleagues and allied professionals, paid and volunteer. # Provide professional support, guidance, and assistance to new DoD SARW professionals to the field in order to promote consistent quality and professionalism in victim assistance. # Obey all applicable Federal, DoD, and Service laws and regulations. III. In her or his professional conduct, the SARC/SAPR VA shall: # Maintain high personal and professional standards in the capacity of a service provider and advocate for victims. # Seek and maintain a proficiency in the delivery of services to victims. # Not discriminate against any victim, employee, colleague, allied professional, or member of the public on the basis of age, sex, disability, ethnicity, race, national origin, religious belief, or sexual orientation. # In accordance with restricted reporting, applicable privileged communications, and all applicable Federal, DoD, and Service privacy laws and regulations, respect the privacy of information provided by the victims served before, during, and after the course of the professional relationship. # Clearly distinguish in public statements representing one's personal views from positions adopted by organizations for which she or he works or is a member, in accordance with Service policy. # Not use her or his official position to secure gifts, monetary rewards, or special privileges or advantages. # Notify competent authorities of the conduct of any colleague or allied professional that constitutes mistreatment of a victim or that brings the profession into disrepute. # Notify competent authorities of any conflict of interest that prevents oneself or a colleague from being able to provide competent services to a victim, or from working cooperatively with colleagues or allied professionals in a victim being impartial in the assistance of any victim. # Notify competent authority immediately if charged, arrested, and/or convicted of any criminal activity. IV. In her or his responsibility to any other profession, the DoD SARW professional will be bound by the ethical standards of the allied profession of which she or he is a member. ---- The certification language is as follows: Certification: I, the undersigned applicant, hereby certify that I have read and agree to follow the Code of Professional Ethics for DoD SARW professionals. I understand that the D-SAACP Certification is subject to surrender on demand to my SARW Program Administrator for cause, and this action may be listed in my permanent record. [ ] I acknowledge that I have read and understand the Code of Ethics for DoD SARW Professionals. | F10: Feature: Learner acknowledges the Code of Ethics As a Learner I want to read and acknowledge the Code of Ethics So that it is clear that I understand them Scenario: Learner views the Code of Ethics Given the learner is logged into the portal When the learner hits 'continue' on the 'Privacy Act Statement Page' they are navigated to the Code of Ethics page Then the learner should see the full text of the Code of Ethics And the learner should have the option to scroll through the content And the learner should see a 'Certification' box where they can acknowledge that they have read and understand the Code of Ethics. Scenario: Learner acknowledges the Code of Ethics Given the learner has viewed the Code of Ethics When the learner clicks the "Acknowledge" checkbox Then the system should record the learner’s acknowledgement And display a confirmation that the acknowledgement was successful Scenario: Learner cannot proceed without acknowledgement Given the learner has not yet acknowledged the Code of Ethics When the learner attempts to submit / initiate application Then the system should prompt the learner to read and acknowledge the Code of Ethics first (mark as incomplete) Scenario: System stores acknowledgement Given the learner has acknowledged the Code of Ethics When an administrator reviews learner records Then the acknowledgement status should be visible within the learner’s application And the timestamp of acknowledgement should be recorded Scenario: Learner re-reads the Code of Ethics Given the learner has already acknowledged the Code of Ethics When the learner navigates back to the Code of Ethics page Then the learner should be able to view the content again And the acknowledgement status should remain recorded | H10: 11523894 | I10: ERM-2865 | J10: Initiate Application | K10: In Progress
A11: Story | B11: ERM-3370 | C11: 11526622 | D11: As a [Learner], I want breadcrumbs that allow me to navigate to different sections of my application | E11: I want persistent breadcrumbs when I start/re-enter my application for every section of the application so I can have visibility on where I am at, AND so I can navigate to different sections as needed. There are 4 types of breadcrumbs: *New Applications - ‘DoD Civilian Sexual Assault Response Workforce Professional’ Position* * Privacy Act > Code of Ethics > Applicant Info > Job Shadow Experience > Recommendations > Review & Send *New Applications - All other Positions* * Privacy Act > Code of Ethics > Applicant Info > Job Shadow Experience > Review & Send *Renewal Applications - ‘DoD Civilian Sexual Assault Response Workforce Professional’ Position* * Privacy Act > Code of Ethics > Applicant Info > Recommendations > CEU Documentation > Review & Send *Renewal Applications - All other Positions* * Privacy Act > Code of Ethics > Applicant Info > CEU Documentation > Review & Send | F11: Background: The application process includes multiple sections. Users need persistent breadcrumbs to see their current location and navigate between sections. There are four breadcrumb flows, depending on application type and position. Scenario 1: New Application – ‘DoD Civilian Sexual Assault Response Workforce Professional’ Position Given the user is starting or re-entering a new application for the ‘DoD Civilian Sexual Assault Response Workforce Professional’ position When the application loads Then the breadcrumb should display: Privacy Act > Code of Ethics > Applicant Info > Job Shadow Experience > Recommendations > Review & Send And the current section should be visually highlighted And the user should be able to click any previous section in the breadcrumb to navigate to it Scenario 2: New Application – All Other Positions Given the user is starting or re-entering a new application for any position other than ‘DoD Civilian Sexual Assault Response Workforce Professional’ When the application loads Then the breadcrumb should display: Privacy Act > Code of Ethics > Applicant Info > Job Shadow Experience > Review & Send And the current section should be visually highlighted And the user should be able to click any previous section in the breadcrumb to navigate to it Scenario 3: Renewal Application – ‘DoD Civilian Sexual Assault Response Workforce Professional’ Position Given the user is starting or re-entering a renewal application for the ‘DoD Civilian Sexual Assault Response Workforce Professional’ position When the application loads Then the breadcrumb should display: Privacy Act > Code of Ethics > Applicant Info > Recommendations > CEU Documentation > Review & Send And the current section should be visually highlighted And the user should be able to click any previous section in the breadcrumb to navigate to it Scenario 4: Renewal Application – All Other Positions Given the user is starting or re-entering a renewal application for any position other than ‘DoD Civilian Sexual Assault Response Workforce Professional’ When the application loads Then the breadcrumb should display: Privacy Act > Code of Ethics > Applicant Info > CEU Documentation > Review & Send And the current section should be visually highlighted And the user should be able to click any previous section in the breadcrumb to navigate to it Scenario 5: Breadcrumb Persistence Given the user navigates between sections of the application When the user moves to a new section Then the breadcrumb should update to reflect the current section And the breadcrumb should remain visible and accurate throughout the application process Scenario 6: Navigation via Breadcrumb Given the user is on any section of the application When the user clicks a previous section in the breadcrumb Then the application should navigate to the selected section And the breadcrumb should update to highlight the new current section | H11: 11523894 | I11: ERM-2865 | J11: Initiate Application | K11: To Do
A12: Story | B12: ERM-3369 | C12: 11526620 | D12: As a [Learner], I want to read a privacy act statement prior to entering in my application information. | E12: Applicant will be able to read the privacy act statement and navigate back to it in the breadcrumbs if needed. Here is the updated Privacy Act Statement Language: Privacy Act Statement *AUTHORITY:* 10 U.S.C. 136, Under Secretary of Defense for Personnel and Readiness; and DoD Instruction 6495.03, Defense Sexual Assault Advocate Certification Program (D-SAACP). *PRINCIPAL PURPOSE(S):* The information on this form will be used to review and process Defense Sexual Assault Advocate Certification Program (D-SAACP) applications for all eligible Department of Defense (DoD) Sexual Assault Response Workforce (SARW) personnel. *ROUTINE USE(S):* To the Department of Justice Office for Victims of Crime and Training Technical Assistance Center for the purpose of verifying certified DoD SARW personnel for participation in Advance Military Sexual Assault Advocate Training. Additional routine uses may be found in the applicable system of records notice DHRA 10, Defense Sexual Assault Advocate Certification Program at: [https://dpcld.defense.gov/Privacy/SORNsIndex/DOD-wide-SORN-Article-View/Article/570562/dhra-10-dod/|https://dpcld.defense.gov/Privacy/SORNsIndex/DOD-wide-SORN-Article-View/Article/570562/dhra-10-dod/|smart-link] *DISCLOSURE:* Mandatory. If you are in an authorized DoD SARW position and you do not complete this form to receive your D-SAACP certification, you will be disqualified from the position. 10 U.S.C. 1561 | F12: Background: Given the user is completing the application form Scenario: Display Privacy Act Statement before application entry Given the user is about to begin the application When the application form loads Then display the full Privacy Act Statement as provided in the ticket description And require the user to view the statement before entering any application information Scenario: Breadcrumb navigation to Privacy Act Statement Given the user is navigating the application form When the user views any step of the application Then display breadcrumb navigation including a link labeled "Privacy Act Statement" And allow the user to return to the Privacy Act Statement at any time Scenario: Privacy Act Statement content accuracy Given the user is viewing the Privacy Act Statement When the statement is displayed Then ensure the text matches exactly the language provided in the ticket, including bold headings and the SORN hyperlink Scenario: Accessibility of Privacy Act Statement Given the user is viewing the Privacy Act Statement When the statement is displayed Then ensure the statement is accessible (screen reader compatible, sufficient contrast, resizable text) | H12: 11523894 | I12: ERM-2865 | J12: Initiate Application | K12: In Progress
A13: Epic | B13: ERM-3368 | C13: 11526586 | D13: Package Application | H13: 11522515 | I13: DTLP-70 | J13: Application Processing | K13: Backlog | L13: EDLM Portal | AF13: SAPRO
A14: Business Requirement | B14: ERM-3366 | C14: 11526519 | D14: The EDLM portal backend shall have an application model to store inputs from the DSAACP application | K14: In Progress | L14: EDLM Portal
A15: Business Requirement | B15: ERM-3365 | C15: 11526486 | D15: The EDLM portal backend shall have an experience model to track and store inputs from the DSCAAP Application | E15: Data Mapping for reference: [20251104_SAPRO Data Fields.xlsx|https://adloffice365.sharepoint.com/:x:/s/EDLM_Extranet/IQCm3aqGu2oPR5FKT4B69P-PAa2mQDBqaiOiYkKTYRDol7s?e=MJkqSH] | K15: In Progress | L15: EDLM Portal
A16: Business Requirement | B16: ERM-3339 | C16: 11526410 | D16: Moodle configurations to outline cohort capabilities and permissions | E16: Ticket for Moodle configuration, adding Moodle documentation for reference. DHRA brand guideline can be found here [DOW Brand Guide | U.S. Department of War|https://www.war.gov/Brand-Guide/] *Moodle Ticket Description:* * Configure the DHRA Moodle instance to support theming for different cohorts or organizational groups (e.g., SAPRO, DHRA), allowing each group to have distinct visual branding as specified in their respective style guides. * Ensure the Moodle landing page presents a DHRA-branded entry point, with navigation to individual cohort/group pages. * Reference and implement branding elements (logo, fonts, colors) from the uploaded DHRA and SAPRO style guides. * Document any technical limitations or dependencies related to theming and cohort separation, especially regarding Edwiser plugin functionality. * This configuration is intended as a bare-bones MVP to demonstrate scalability for additional DHRA organizations in the future. | K16: To Do
A17: Business Requirement | B17: ERM-3335 | C17: 11526342 | D17: EDLM Portal shall store personnel information in support of the DSAACP application intake | E17: Build out data fields for DSAACP application - the data will NOT be prepopulated as a part of this ticket. Create APIs for editing fields. Data mapping spreadsheet for reference: [https://adloffice365.sharepoint.com/:x:/s/EDLM_Extranet/IQCm3aqGu2oPR5FKT4B69P-PAa2mQDBqaiOiYkKTYRDol7s?e=MSnd5S|https://adloffice365.sharepoint.com/:x:/s/EDLM_Extranet/IQCm3aqGu2oPR5FKT4B69P-PAa2mQDBqaiOiYkKTYRDol7s?e=MSnd5S|smart-link] | H17: 11515253 | I17: ERM-138 | J17: Portal: Baseline Functional Requirements | K17: In Progress | L17: EDLM Portal
A18: Story | B18: ERM-3330 | C18: 11526269 | D18: As a [Learner], I want to be notified of expiring certification so I can ensure I complete renewal requirements | E18: certification expires every XX years/months. Users should be sent an email reminder XX months prior to expiration. in UI displaying past applications, there should be an indicator of upcoming expiry as well. _User should also see a notification in their learning summary_ | F18: Feature: Learner Certification Expiry Notifications As a Learner I want to be notified of expiring certification So that I can ensure I complete renewal requirements on time Scenario: Learner receives advance notification of certification expiry Given I have an active certification with a defined expiry date When the certification is 90 days from expiry Then I should receive a notification reminding me of the upcoming expiry And the notification should include instructions for renewal Scenario: Learner receives reminder closer to expiry Given I have an active certification with a defined expiry date When the certification is 30 days from expiry Then I should receive a notification reminding me of the upcoming expiry And the notification should include a link to renewal requirements Scenario: Learner receives final reminder before expiry Given I have an active certification with a defined expiry date When the certification is 7 days from expiry Then I should receive a final notification warning me of imminent expiry And the notification should highlight urgent action required Scenario: Learner views certification status Given I am logged into the system When I navigate to my certification dashboard Then I should see the expiry date for each certification And it should indicate if the expiry date is approaching Scenario: Learner completes renewal requirements Given I have received a notification of expiring certification When I complete the renewal requirements (apply as renewal applicant, be approved) Then my certification status should update to "Renewed" And I should receive a confirmation notification of successful renewal/ re-certification Scenario: Certification expires without renewal Given I have not completed renewal requirements When the certification expiry date passes Then my certification status should update to "Expired" And I should receive a notification informing me that the certification has expired | K18: Backlog
A19: Story | B19: ERM-3326 | C19: 11526262 | D19: As a [Learner], I want to select the type, frequency, and method for how I am receiving notifications. | E19: we should have US for this already in existing Baseline capabilities. Configure to SAPRO specific notifications. UI & email notifications? | F19: Feature: Learner Notification Preferences As a Learner I want to select the type, frequency, and method for how I am receiving notifications So that I can control how I stay informed without being overwhelmed Scenario: Learner selects notification type Given I am logged into the system When I navigate to the notification settings Then I should be able to choose notification types such as "Application Status", "Course Updates", and "Certificate Issuance" And my selection should be saved and applied to future notifications Scenario: Learner selects notification frequency Given I am on the notification settings page When I choose a frequency option such as "Immediate", "Daily Summary", or "Weekly Digest" Then the system should deliver notifications according to my chosen frequency And I should receive a confirmation of my preference change Scenario: Learner selects notification method Given I am on the notification settings page When I choose a method such as "Email" or "In-App" Then the system should deliver notifications using my selected method And I should be able to update or change this method at any time Scenario: Learner updates preferences Given I have previously set notification preferences When I change the type, frequency, or method Then the system should immediately update my preferences And I should receive a confirmation message of the updated settings Scenario: Learner disables notifications Given I am on the notification settings page When I choose to disable a notification type Then I should no longer receive notifications of that type And the system should reflect the disabled status in my settings Scenario: Learner views current preferences Given I am logged into the system When I navigate to the notification settings Then I should see my current selections for type, frequency, and method And each preference should be clearly displayed and editable | H19: 11523898 | I19: ERM-2867 | J19: Monitor Application Intake and Validation | K19: Backlog
A20: Story | B20: ERM-3322 | C20: 11526255 | D20: As a [Learner], I want to monitor my application status all the way through submission, final approval, and certificate issuance | E20: For MVP, these may be email notification rather than in-app? Applicants should receive notifications of their application’s progress, creating improved transparency throughout the process. Applicants will also be able to view their application status in the ‘applications’ page. | F20: Feature: Learner Application Status Tracking and Notifications As a Learner I want to be notified and keep track of my application status So that I am aware of progress from submission to certificate issuance Scenario: Learner submits an application Given I have completed and submitted my application When the system receives my application Then I should see my application status as "Submitted" And I should receive a notification confirming submission Scenario: Application moves to review stage Given my application has been submitted When the application is under review Then I should see my application status as "In Review" And I should receive a notification that my application is being reviewed Scenario: Application receives final approval Given my application is under review When the application is approved Then I should see my application status as "Approved" And I should receive a notification confirming approval Scenario: Certificate is issued Given my application has been approved When the certificate is generated Then I should see my application status as "Certificate Issued" And I should receive a notification with details on accessing my certificate Scenario: Learner views application history Given I am logged into the system When I navigate to my application dashboard Then I should see a timeline of statuses including "Submitted", "In Review", "Approved", and "Certificate Issued" And each status should display the corresponding date and notification details | H20: 11523898 | I20: ERM-2867 | J20: Monitor Application Intake and Validation | K20: Backlog
A21: Story | B21: ERM-3314 | C21: 11526181 | D21: As a [Learner], I want to download my completed application | E21: After I have completed my application, and it has been filled out completely by the required individuals (e.g., SARC, Supervisor, CO, previous Supervisors…) I want to be able to access it, view my application and download it so I can share it or discuss it as/if needed. Updated Form TBD. | F21: Scenario: Learner downloads a completed application successfully Given the learner has initiated the application and all reviewers have complete their section and the application has been sent to NOVA. And the learner is logged into the system When the learner navigates to the "My Applications" page And selects the completed application And clicks the "Download" button Then the system should generate a downloadable file of the application And the file format should be PDF And the download should start automatically And the file should contain all submitted application details Scenario: Download option is not available for incomplete applications Given the learner has an application that is not yet completed When the learner views the application details Then the "Download" button should not be visible Scenario: Error handling when download fails Given the learner has completed and submitted the application And the learner is logged into the system When the learner clicks the "Download" button And the system encounters an error generating the file Then the system should display an error message | H21: 11523894 | I21: ERM-2865 | J21: Initiate Application | K21: Backlog | AF21: SAPRO
A22: Business Requirement | B22: ERM-3311 | C22: 11526113 | D22: . Any updates made shall be saved and reflected accurately in future IDP views or exports. | K22: To Do
A23: Business Requirement | B23: ERM-3310 | C23: 11526112 | D23: Any updates made shall be saved and reflected accurately in future IDP views or exports. | E23: *Title:* ERM-2468 Sub – Persist Updates Across IDP Views/Exports *Description:* Any updates made shall be saved and reflected accurately in future IDP views or exports. *Acceptance Criteria:* * Changes persist after session ends. * Exported IDP matches latest saved version. * Version control maintained for audit. | H23: 11515245 | I23: ERM-136 | J23: TM: Learning and Development | K23: Backlog
A24: Business Requirement | B24: ERM-3309 | C24: 11526111 | D24: Only user-editable sections may be changed; system-generated data shall remain locked. | E24: *Title:* ERM-2468 Sub ticket – Lock System-Generated Data *Description:* Only user-editable sections may be changed; system-generated data shall remain locked. *Acceptance Criteria:* * Editable fields: goals, objectives, activities. * Locked fields: personnel data, system-calculated metrics. * Attempted edits on locked fields trigger error message. | H24: 11515245 | I24: ERM-136 | J24: TM: Learning and Development | K24: Done
A25: Business Requirement | B25: ERM-3308 | C25: 11526110 | D25: The Learner shall be able to download or share the completed IDP with their supervisor. | E25: *Title:* ERM-2468 Sub ticket – Enable Download/Share of Completed IDP *Description:* The learner shall be able to download or share the completed IDP with their supervisor. *Acceptance Criteria:* * Download option available in PDF format. * Share option sends IDP via secure link or email to supervisor. * Audit log captures share/download actions. | H25: 11515245 | I25: ERM-136 | J25: TM: Learning and Development | K25: Backlog
